Workbook

Sheet LeesMij
A1: ART EYE — FINANCIEEL MODEL (36 maanden, maandelijks, 3 scenario's)
A2: Alle bedragen in A$ (AUD). Start = M1 = september 2026 (beta-launch rond Sydney Contemporary, 10-13 sep, Carriageworks).
A4: KLEURCODE
A5: Blauwe tekst = harde input / aanname (aanpasbaar). Zwart = formule. Groen = verwijzing naar ander blad. Gele vulling = kernaanname — begin hier met draaien.
A7: STRUCTUUR
A8: 1. Aannames — alle drivers, kolommen Bear / Basis / Bull, met bron/redenering per regel.
A9: 2. Retentie — maandelijkse cohort-retentiecurves (leeftijd 0-35 mnd) per scenario. Low-frequency use case: steile val na M1, plateau daarna.
A10: 3. ModelBear / ModelBasis / ModelBull — 36 maandregels: downloads, activatie, cohort-MAU, premium, venue-SaaS, fairs, kosten, cashflow. KPI-blok onderaan.
A11: 4. CohortBear/-Basis/-Bull — het volledige cohortdriehoek: rij = startcohort, kolom = kalendermaand; MAU = kolomsom. Model-MAU verwijst hierheen.
A12: 5. Sensitiviteit — live gevoeligheidstabellen (venue-MRR, consumer-omzet, venue-LTV).
A14: KERNCONCLUSIES (Basis-scenario)
A15: - Consumer-LTV per geactiveerde gebruiker is < A$1: consumer subscription kan NOOIT het verdienmodel zijn; hij bestaat alleen als bonus.
... A22: Volledige redenering: docs/finance/ART-EYE-financieel-strategieplan.md in deze repo.

Sheet Retentie
A1: Leeftijd (mnd) | B1: Bear | C1: Basis | D1: Bull | F1: Aandeel van een maandcohort dat in maand N na activatie nog actief is (>=1 sessie). IJkpunten: event-gedreven consumer apps halen D30 10-15% (Basis M1=40% van geactiveerden, niet van downloads); plateau 8-10% = de kern-loggers (Letterboxd-patroon voor niche-logboek-apps). Bear = geen habit; Bull = statusloop werkt.
A2: 0 | B2: 1 | C2: 1 | D2: 1
A3: 1 | B3: 0.28 | C3: 0.4 | D3: 0.52
A4: 2 | B4: 0.18 | C4: 0.3 | D4: 0.42
A5: 3 | B5: 0.13 | C5: 0.24 | D5: 0.35
A6: 4 | B6: 0.1 | C6: 0.2 | D6: 0.31
A7: 5 | B7: 0.085 | C7: 0.18 | D7: 0.28
A8: 6 | B8: 0.075 | C8: 0.16 | D8: 0.26
A9: 7 | B9: 0.068 | C9: 0.15 | D9: 0.245
A10: 8 | B10: 0.062 | C10: 0.14 | D10: 0.235
A11: 9 | B11: 0.058 | C11: 0.13 | D11: 0.225
A12: 10 | B12: 0.054 | C12: 0.12 | D12: 0.215
A13: 11 | B13: 0.051 | C13: 0.115 | D13: 0.21
... A37: 35 | B37: 0.027 | C37: 0.081 | D37: 0.17
A38: Som (verwachte actieve mnd) | B38: =SUM(B2:B37) -> 2.99 | C38: =SUM(C2:C37) -> 5.376 | D38: =SUM(D2:D37) -> 8.674

Sheet Aannames
A1: AANNAMES — alle bedragen A$; percentages als fractie
A2: Driver | B2: Bear | C2: Basis | D2: Bull | E2: Redenering / bron
A3: CONSUMER
A4: Launch-downloads M1 (sep '26) | B4: 500 | C4: 900 | D4: 1500 | E4: Fair-weekend Sydney Contemporary (~25-30k bezoekers) + pers + posters bij venues. 900 = 3% van fairbezoek; geen betaalde installs.
A5: Organische downloads/mnd (start) | B5: 140 | C5: 260 | D5: 400 | E5: ASO 'sydney art exhibitions', venue-QR's, Instagram-shares. Referentie: niche-stadsapps zonder budget.
A6: Groei organisch %/mnd | B6: 0 | C6: 0.04 | D6: 0.06 | E6: Word-of-mouth + registergroei. Bear: geen loop, vlak.
A7: Fair-boost (extra % in sept) | B7: 0.8 | C7: 1.5 | D7: 2.5 | E7: Elke september (Sydney Contemporary) piekt discovery; M13/M25.
A8: Activatie (signup + >=1 save) | B8: 0.45 | C8: 0.55 | D8: 0.62 | E8: App vraagt account voor kernloop; benchmark consumer 40-60%. Meetbaar maken in analytics (nu NIET geinstrumenteerd in de code!).
A9: Premium-conversie (% van MAU) | B9: 0.01 | C9: 0.025 | D9: 0.04 | E9: Letterboxd Pro-achtig: 1-5% van actieven betaalt voor stats/Wrapped/vroege fairgidsen.
A10: Premium-prijs A$/mnd | B10: 4.49 | C10: 4.49 | D10: 5.99 | E10: Onder de koffie-drempel; jaarplan later (A$34.99).
A11: App Store-fee | B11: 0.15 | C11: 0.15 | D11: 0.15 | E11: Apple Small Business Program (<US$1M omzet) = 15%, geen 30%.
A12: Retentiecurve | E12: Zie blad Retentie (kolom per scenario) — de belangrijkste aanname van dit hele model.
A13: VENUE-SAAS
A14: Start verkoop (maand #) | B14: 9 | C14: 7 | D14: 6 | E14: Pas verkopen met bewijs: >=1.500 MAU + doorkliks per venue meetbaar. Eerder pitchen verbrandt de markt.
A15: Outreach venues/mnd | B15: 12 | C15: 20 | D15: 25 | E15: Avondwerk-plafond: ~5 gerichte pitches/week (e-mail + 1 bezoek). Solo-constraint, geen sales-team.
A16: Close rate | B16: 0.06 | C16: 0.12 | D16: 0.18 | E16: Galeries betalen al voor listings (Art Guide Australia / Art Almanac): budgetregel bestaat. 12% = 1 op 8 pitches.
A17: Venue-prijs A$/mnd | B17: 39 | C17: 45 | D17: 55 | E17: Onder Art Guide-print-listingtarief; featured plaatsing + analytics + eigen media (foto/video/reel) + claim.
A18: Venue-churn %/mnd | B18: 0.05 | C18: 0.025 | D18: 0.015 | E18: Kleine galeries sluiten/bezuinigen; 2,5%/mnd = ~26%/jaar. Skok: netto-retentie is de hele SaaS-case.
A19: Adresseerbare venues Sydney | B19: 60 | C19: 70 | D19: 80 | E19: Register telt 143 venues (104 galleries/23 musea/16 ARI's); alleen commerciele galeries + betaalkrachtige non-profits kopen.
A20: Max. penetratie | B20: 0.25 | C20: 0.35 | D20: 0.45 | E20: Art Guide haalt vergelijkbare dekking in AU; nooit 100% — een deel betaalt nooit ergens voor.
A21: Venue-CAC (A$) | B21: 150 | C21: 120 | D21: 100 | E21: Founder-tijd + bezoek + demo; geen betaalde acquisitie.
A22: Venue-brutomarge | B22: 0.92 | C22: 0.94 | D22: 0.95 | E22: Stripe-fees + support-tijd; software-marge.
A23: EXPANSIE
A24: Stad 2 launch (maand #) | B24: 99 | C24: 18 | D24: 13 | E24: Alleen na Sydney-gates (zie strategiedoc §4). Basis: Melbourne, feb '28 rond Melbourne Art Fair. Bear: nooit (99).
A25: Adresseerbare venues stad 2 | B25: 0 | C25: 85 | D25: 170 | E25: Melbourne heeft meer galeries dan Sydney; Bull bundelt Melbourne+Brisbane.
A26: Organische downloads/mnd stad 2 | B26: 0 | C26: 300 | D26: 500 | E26: Zelfde playbook, maar met bewijs + AU-pers uit Sydney.
A27: KOSTEN (A$/mnd tenzij anders)
A28: Infra basis (Supabase Pro e.d.) | B28: 60 | C28: 60 | D28: 60 | E28: Supabase Pro US$25 + storage/egress + Vercel/EAS-basis.
A29: Infra per MAU | B29: 0.02 | C29: 0.02 | D29: 0.02 | E29: Egress/beeld-CDN schaalt met gebruik.
A30: AI-pipeline per stad | B30: 80 | C30: 80 | D30: 80 | E30: Claude-calls validate/discover/enrich (cap 30 calls/run, zie supabase/functions) + web search.
A31: Tools (EAS, Resend, domein, mail) | B31: 70 | C31: 70 | D31: 70 | E31: Expo EAS production US$0-99, Resend, domein, e-mail.
A32: Apple Developer /jaar | B32: 150 | C32: 150 | D32: 150 | E32: US$99/jr; valt in M1, M13, M25.
A33: Marketing basis | B33: 50 | C33: 150 | D33: 300 | E33: Posters, print bij venues, af en toe een boost. Geen structurele paid acquisitie.
A34: Fair-marketing (elke sept) | B34: 300 | C34: 800 | D34: 1500 | E34: Posters/QR rond Sydney Contemporary; guerrilla, geen stand.
A35: Oprichting/legal eenmalig (M1) | B35: 400 | C35: 400 | D35: 400 | E35: Sole trader ABN + voorwaarden/privacy-templates. Pty Ltd pas bij venue-omzet.
A36: OVERIG
A37: Fair-partnership A$ (per sept, v.a. jr 2) | B37: 0 | C37: 5000 | D37: 10000 | E37: Officiele agenda-partner/gids van 1 fair. Distributie-deal eerst, geld pas met bewezen publiek. Lumpy — nooit primair.

Sheet ModelBear
A1: ART EYE — scenario BEAR (A$, M1 = sep 2026)
A2: Alle regels zijn formules op blad Aannames + Retentie. Niets hier hard aanpassen.
A7: Mnd | B7: Kalender | C7: Downloads Sydney | D7: Downloads stad 2+ | E7: Downloads totaal | F7: Nieuwe actieven | G7: MAU (cohort) | H7: Premium-abonnees | I7: Consumer-omzet netto | J7: Betalende venues | K7: Venue-MRR | L7: Fair/partnership | M7: Totale omzet | N7: Infra | O7: AI-pipeline | P7: Tools | Q7: Apple | R7: Marketing | S7: Eenmalig | T7: Totale kosten | U7: Netto cashflow | V7: Cumulatief
A8: 1 | B8: sep-26 | C8: =Aannames!$B$4 -> 500 | D8: =IF(A8>=Aannames!$B$24,Aannames!$B$26*(1+Aannames!$B$6)^(A8-Aannames!$B$24),0) -> 0 | E8: =C8+D8 -> 500 | F8: =E8*Aannames!$B$8 -> 225 | G8: =CohortBear!B$38 -> 225 | H8: =G8*Aannames!$B$9 -> 2.25 | I8: =H8*Aannames!$B$10*(1-Aannames!$B$11) -> 8.587125 | J8: =MIN(IF(A8>=Aannames!$B$14,Aannames!$B$15*Aannames!$B$16,0),(Aannames!$B$19+IF(A8>=Aannames!$B$24,Aannames!$B$25,0))*Aannames!$B$20) -> 0 | K8: =J8*Aannames!$B$17 -> 0 | L8: =IF(AND(A8>12,MOD(A8-1,12)=0),Aannames!$B$37,0) -> 0 | M8: =I8+K8+L8 -> 8.587125 | N8: =Aannames!$B$28+G8*Aannames!$B$29 -> 64.5 | O8: =Aannames!$B$30*(1+IF(A8>=Aannames!$B$24,1,0)) -> 80 | P8: =Aannames!$B$31 -> 70 | Q8: =IF(MOD(A8-1,12)=0,Aannames!$B$32,0) -> 150 | R8: =Aannames!$B$33+IF(MOD(A8-1,12)=0,Aannames!$B$34,0) -> 350 | S8: =IF(A8=1,Aannames!$B$35,0) -> 400 | T8: =SUM(N8:S8) -> 1114.5 | U8: =M8-T8 -> -1105.9129 | V8: =U8 -> -1105.9129
A9: 2 | B9: okt-26 | C9: =Aannames!$B$5*(1+Aannames!$B$6)^(A9-2)*(1+IF(MOD(A9-1,12)=0,Aannames!$B$7,0)) -> 140 | D9: =IF(A9>=Aannames!$B$24,Aannames!$B$26*(1+Aannames!$B$6)^(A9-Aannames!$B$24),0) -> 0 | E9: =C9+D9 -> 140 | F9: =E9*Aannames!$B$8 -> 63 | G9: =CohortBear!C$38 -> 126 | H9: =G9*Aannames!$B$9 -> 1.26 | I9: =H9*Aannames!$B$10*(1-Aannames!$B$11) -> 4.80879 | J9: =MIN(J8*(1-Aannames!$B$18)+IF(A9>=Aannames!$B$14,Aannames!$B$15*Aannames!$B$16,0),(Aannames!$B$19+IF(A9>=Aannames!$B$24,Aannames!$B$25,0))*Aannames!$B$20) -> 0 | K9: =J9*Aannames!$B$17 -> 0 | L9: =IF(AND(A9>12,MOD(A9-1,12)=0),Aannames!$B$37,0) -> 0 | M9: =I9+K9+L9 -> 4.80879 | N9: =Aannames!$B$28+G9*Aannames!$B$29 -> 62.52 | O9: =Aannames!$B$30*(1+IF(A9>=Aannames!$B$24,1,0)) -> 80 | P9: =Aannames!$B$31 -> 70 | Q9: =IF(MOD(A9-1,12)=0,Aannames!$B$32,0) -> 0 | R9: =Aannames!$B$33+IF(MOD(A9-1,12)=0,Aannames!$B$34,0) -> 50 | S9: =IF(A9=1,Aannames!$B$35,0) -> 0 | T9: =SUM(N9:S9) -> 262.52 | U9: =M9-T9 -> -257.71121 | V9: =V8+U9 -> -1363.6241
A10: 3 | B10: nov-26 | C10: =Aannames!$B$5*(1+Aannames!$B$6)^(A10-2)*(1+IF(MOD(A10-1,12)=0,Aannames!$B$7,0)) -> 140 | D10: =IF(A10>=Aannames!$B$24,Aannames!$B$26*(1+Aannames!$B$6)^(A10-Aannames!$B$24),0) -> 0 | E10: =C10+D10 -> 140 | F10: =E10*Aannames!$B$8 -> 63 | G10: =CohortBear!D$38 -> 121.14 | H10: =G10*Aannames!$B$9 -> 1.2114 | I10: =H10*Aannames!$B$10*(1-Aannames!$B$11) -> 4.6233081 | J10: =MIN(J9*(1-Aannames!$B$18)+IF(A10>=Aannames!$B$14,Aannames!$B$15*Aannames!$B$16,0),(Aannames!$B$19+IF(A10>=Aannames!$B$24,Aannames!$B$25,0))*Aannames!$B$20) -> 0 | K10: =J10*Aannames!$B$17 -> 0 | L10: =IF(AND(A10>12,MOD(A10-1,12)=0),Aannames!$B$37,0) -> 0 | M10: =I10+K10+L10 -> 4.6233081 | N10: =Aannames!$B$28+G10*Aannames!$B$29 -> 62.4228 | O10: =Aannames!$B$30*(1+IF(A10>=Aannames!$B$24,1,0)) -> 80 | P10: =Aannames!$B$31 -> 70 | Q10: =IF(MOD(A10-1,12)=0,Aannames!$B$32,0) -> 0 | R10: =Aannames!$B$33+IF(MOD(A10-1,12)=0,Aannames!$B$34,0) -> 50 | S10: =IF(A10=1,Aannames!$B$35,0) -> 0 | T10: =SUM(N10:S10) -> 262.4228 | U10: =M10-T10 -> -257.79949 | V10: =V9+U10 -> -1621.4236
A11: 4 | B11: dec-26 | C11: =Aannames!$B$5*(1+Aannames!$B$6)^(A11-2)*(1+IF(MOD(A11-1,12)=0,Aannames!$B$7,0)) -> 140 | D11: =IF(A11>=Aannames!$B$24,Aannames!$B$26*(1+Aannames!$B$6)^(A11-Aannames!$B$24),0) -> 0 | E11: =C11+D11 -> 140 | F11: =E11*Aannames!$B$8 -> 63 | G11: =CohortBear!E$38 -> 121.23 | H11: =G11*Aannames!$B$9 -> 1.2123 | I11: =H11*Aannames!$B$10*(1-Aannames!$B$11) -> 4.6267429 | J11: =MIN(J10*(1-Aannames!$B$18)+IF(A11>=Aannames!$B$14,Aannames!$B$15*Aannames!$B$16,0),(Aannames!$B$19+IF(A11>=Aannames!$B$24,Aannames!$B$25,0))*Aannames!$B$20) -> 0 | K11: =J11*Aannames!$B$17 -> 0 | L11: =IF(AND(A11>12,MOD(A11-1,12)=0),Aannames!$B$37,0) -> 0 | M11: =I11+K11+L11 -> 4.6267429 | N11: =Aannames!$B$28+G11*Aannames!$B$29 -> 62.4246 | O11: =Aannames!$B$30*(1+IF(A11>=Aannames!$B$24,1,0)) -> 80 | P11: =Aannames!$B$31 -> 70 | Q11: =IF(MOD(A11-1,12)=0,Aannames!$B$32,0) -> 0 | R11: =Aannames!$B$33+IF(MOD(A11-1,12)=0,Aannames!$B$34,0) -> 50 | S11: =IF(A11=1,Aannames!$B$35,0) -> 0 | T11: =SUM(N11:S11) -> 262.4246 | U11: =M11-T11 -> -257.79786 | V11: =V10+U11 -> -1879.2214
A12: 5 | B12: jan-27 | C12: =Aannames!$B$5*(1+Aannames!$B$6)^(A12-2)*(1+IF(MOD(A12-1,12)=0,Aannames!$B$7,0)) -> 140 | D12: =IF(A12>=Aannames!$B$24,Aannames!$B$26*(1+Aannames!$B$6)^(A12-Aannames!$B$24),0) -> 0 | E12: =C12+D12 -> 140 | F12: =E12*Aannames!$B$8 -> 63 | G12: =CohortBear!F$38 -> 122.67 | H12: =G12*Aannames!$B$9 -> 1.2267 | I12: =H12*Aannames!$B$10*(1-Aannames!$B$11) -> 4.6817006 | J12: =MIN(J11*(1-Aannames!$B$18)+IF(A12>=Aannames!$B$14,Aannames!$B$15*Aannames!$B$16,0),(Aannames!$B$19+IF(A12>=Aannames!$B$24,Aannames!$B$25,0))*Aannames!$B$20) -> 0 | K12: =J12*Aannames!$B$17 -> 0 | L12: =IF(AND(A12>12,MOD(A12-1,12)=0),Aannames!$B$37,0) -> 0 | M12: =I12+K12+L12 -> 4.6817006 | N12: =Aannames!$B$28+G12*Aannames!$B$29 -> 62.4534 | O12: =Aannames!$B$30*(1+IF(A12>=Aannames!$B$24,1,0)) -> 80 | P12: =Aannames!$B$31 -> 70 | Q12: =IF(MOD(A12-1,12)=0,Aannames!$B$32,0) -> 0 | R12: =Aannames!$B$33+IF(MOD(A12-1,12)=0,Aannames!$B$34,0) -> 50 | S12: =IF(A12=1,Aannames!$B$35,0) -> 0 | T12: =SUM(N12:S12) -> 262.4534 | U12: =M12-T12 -> -257.7717 | V12: =V11+U12 -> -2136.9931
A13: 6 | B13: feb-27 | C13: =Aannames!$B$5*(1+Aannames!$B$6)^(A13-2)*(1+IF(MOD(A13-1,12)=0,Aannames!$B$7,0)) -> 140 | D13: =IF(A13>=Aannames!$B$24,Aannames!$B$26*(1+Aannames!$B$6)^(A13-Aannames!$B$24),0) -> 0 | E13: =C13+D13 -> 140 | F13: =E13*Aannames!$B$8 -> 63 | G13: =CohortBear!G$38 -> 125.595 | H13: =G13*Aannames!$B$9 -> 1.25595 | I13: =H13*Aannames!$B$10*(1-Aannames!$B$11) -> 4.7933332 | J13: =MIN(J12*(1-Aannames!$B$18)+IF(A13>=Aannames!$B$14,Aannames!$B$15*Aannames!$B$16,0),(Aannames!$B$19+IF(A13>=Aannames!$B$24,Aannames!$B$25,0))*Aannames!$B$20) -> 0 | K13: =J13*Aannames!$B$17 -> 0 | L13: =IF(AND(A13>12,MOD(A13-1,12)=0),Aannames!$B$37,0) -> 0 | M13: =I13+K13+L13 -> 4.7933332 | N13: =Aannames!$B$28+G13*Aannames!$B$29 -> 62.5119 | O13: =Aannames!$B$30*(1+IF(A13>=Aannames!$B$24,1,0)) -> 80 | P13: =Aannames!$B$31 -> 70 | Q13: =IF(MOD(A13-1,12)=0,Aannames!$B$32,0) -> 0 | R13: =Aannames!$B$33+IF(MOD(A13-1,12)=0,Aannames!$B$34,0) -> 50 | S13: =IF(A13=1,Aannames!$B$35,0) -> 0 | T13: =SUM(N13:S13) -> 262.5119 | U13: =M13-T13 -> -257.71857 | V13: =V12+U13 -> -2394.7117
A14: 7 | B14: mrt-27 | C14: =Aannames!$B$5*(1+Aannames!$B$6)^(A14-2)*(1+IF(MOD(A14-1,12)=0,Aannames!$B$7,0)) -> 140 | D14: =IF(A14>=Aannames!$B$24,Aannames!$B$26*(1+Aannames!$B$6)^(A14-Aannames!$B$24),0) -> 0 | E14: =C14+D14 -> 140 | F14: =E14*Aannames!$B$8 -> 63 | G14: =CohortBear!H$38 -> 128.7 | H14: =G14*Aannames!$B$9 -> 1.287 | I14: =H14*Aannames!$B$10*(1-Aannames!$B$11) -> 4.9118355 | J14: =MIN(J13*(1-Aannames!$B$18)+IF(A14>=Aannames!$B$14,Aannames!$B$15*Aannames!$B$16,0),(Aannames!$B$19+IF(A14>=Aannames!$B$24,Aannames!$B$25,0))*Aannames!$B$20) -> 0 | K14: =J14*Aannames!$B$17 -> 0 | L14: =IF(AND(A14>12,MOD(A14-1,12)=0),Aannames!$B$37,0) -> 0 | M14: =I14+K14+L14 -> 4.9118355 | N14: =Aannames!$B$28+G14*Aannames!$B$29 -> 62.574 | O14: =Aannames!$B$30*(1+IF(A14>=Aannames!$B$24,1,0)) -> 80 | P14: =Aannames!$B$31 -> 70 | Q14: =IF(MOD(A14-1,12)=0,Aannames!$B$32,0) -> 0 | R14: =Aannames!$B$33+IF(MOD(A14-1,12)=0,Aannames!$B$34,0) -> 50 | S14: =IF(A14=1,Aannames!$B$35,0) -> 0 | T14: =SUM(N14:S14) -> 262.574 | U14: =M14-T14 -> -257.66216 | V14: =V13+U14 -> -2652.3739
A15: 8 | B15: apr-27 | C15: =Aannames!$B$5*(1+Aannames!$B$6)^(A15-2)*(1+IF(MOD(A15-1,12)=0,Aannames!$B$7,0)) -> 140 | D15: =IF(A15>=Aannames!$B$24,Aannames!$B$26*(1+Aannames!$B$6)^(A15-Aannames!$B$24),0) -> 0 | E15: =C15+D15 -> 140 | F15: =E15*Aannames!$B$8 -> 63 | G15: =CohortBear!I$38 -> 131.85 | H15: =G15*Aannames!$B$9 -> 1.3185 | I15: =H15*Aannames!$B$10*(1-Aannames!$B$11) -> 5.0320552 | J15: =MIN(J14*(1-Aannames!$B$18)+IF(A15>=Aannames!$B$14,Aannames!$B$15*Aannames!$B$16,0),(Aannames!$B$19+IF(A15>=Aannames!$B$24,Aannames!$B$25,0))*Aannames!$B$20) -> 0 | K15: =J15*Aannames!$B$17 -> 0 | L15: =IF(AND(A15>12,MOD(A15-1,12)=0),Aannames!$B$37,0) -> 0 | M15: =I15+K15+L15 -> 5.0320552 | N15: =Aannames!$B$28+G15*Aannames!$B$29 -> 62.637 | O15: =Aannames!$B$30*(1+IF(A15>=Aannames!$B$24,1,0)) -> 80 | P15: =Aannames!$B$31 -> 70 | Q15: =IF(MOD(A15-1,12)=0,Aannames!$B$32,0) -> 0 | R15: =Aannames!$B$33+IF(MOD(A15-1,12)=0,Aannames!$B$34,0) -> 50 | S15: =IF(A15=1,Aannames!$B$35,0) -> 0 | T15: =SUM(N15:S15) -> 262.637 | U15: =M15-T15 -> -257.60494 | V15: =V14+U15 -> -2909.9788
A16: 9 | B16: mei-27 | C16: =Aannames!$B$5*(1+Aannames!$B$6)^(A16-2)*(1+IF(MOD(A16-1,12)=0,Aannames!$B$7,0)) -> 140 | D16: =IF(A16>=Aannames!$B$24,Aannames!$B$26*(1+Aannames!$B$6)^(A16-Aannames!$B$24),0) -> 0 | E16: =C16+D16 -> 140 | F16: =E16*Aannames!$B$8 -> 63 | G16: =CohortBear!J$38 -> 134.784 | H16: =G16*Aannames!$B$9 -> 1.34784 | I16: =H16*Aannames!$B$10*(1-Aannames!$B$11) -> 5.1440314 | J16: =MIN(J15*(1-Aannames!$B$18)+IF(A16>=Aannames!$B$14,Aannames!$B$15*Aannames!$B$16,0),(Aannames!$B$19+IF(A16>=Aannames!$B$24,Aannames!$B$25,0))*Aannames!$B$20) -> 0.72 | K16: =J16*Aannames!$B$17 -> 28.08 | L16: =IF(AND(A16>12,MOD(A16-1,12)=0),Aannames!$B$37,0) -> 0 | M16: =I16+K16+L16 -> 33.224031 | N16: =Aannames!$B$28+G16*Aannames!$B$29 -> 62.69568 | O16: =Aannames!$B$30*(1+IF(A16>=Aannames!$B$24,1,0)) -> 80 | P16: =Aannames!$B$31 -> 70 | Q16: =IF(MOD(A16-1,12)=0,Aannames!$B$32,0) -> 0 | R16: =Aannames!$B$33+IF(MOD(A16-1,12)=0,Aannames!$B$34,0) -> 50 | S16: =IF(A16=1,Aannames!$B$35,0) -> 0 | T16: =SUM(N16:S16) -> 262.69568 | U16: =M16-T16 -> -229.47165 | V16: =V15+U16 -> -3139.4505
A17: 10 | B17: jun-27 | C17: =Aannames!$B$5*(1+Aannames!$B$6)^(A17-2)*(1+IF(MOD(A17-1,12)=0,Aannames!$B$7,0)) -> 140 | D17: =IF(A17>=Aannames!$B$24,Aannames!$B$26*(1+Aannames!$B$6)^(A17-Aannames!$B$24),0) -> 0 | E17: =C17+D17 -> 140 | F17: =E17*Aannames!$B$8 -> 63 | G17: =CohortBear!K$38 -> 137.79 | H17: =G17*Aannames!$B$9 -> 1.3779 | I17: =H17*Aannames!$B$10*(1-Aannames!$B$11) -> 5.2587554 | J17: =MIN(J16*(1-Aannames!$B$18)+IF(A17>=Aannames!$B$14,Aannames!$B$15*Aannames!$B$16,0),(Aannames!$B$19+IF(A17>=Aannames!$B$24,Aannames!$B$25,0))*Aannames!$B$20) -> 1.404 | K17: =J17*Aannames!$B$17 -> 54.756 | L17: =IF(AND(A17>12,MOD(A17-1,12)=0),Aannames!$B$37,0) -> 0 | M17: =I17+K17+L17 -> 60.014755 | N17: =Aannames!$B$28+G17*Aannames!$B$29 -> 62.7558 | O17: =Aannames!$B$30*(1+IF(A17>=Aannames!$B$24,1,0)) -> 80 | P17: =Aannames!$B$31 -> 70 | Q17: =IF(MOD(A17-1,12)=0,Aannames!$B$32,0) -> 0 | R17: =Aannames!$B$33+IF(MOD(A17-1,12)=0,Aannames!$B$34,0) -> 50 | S17: =IF(A17=1,Aannames!$B$35,0) -> 0 | T17: =SUM(N17:S17) -> 262.7558 | U17: =M17-T17 -> -202.74104 | V17: =V16+U17 -> -3342.1915
A18: 11 | B18: jul-27 | C18: =Aannames!$B$5*(1+Aannames!$B$6)^(A18-2)*(1+IF(MOD(A18-1,12)=0,Aannames!$B$7,0)) -> 140 | D18: =IF(A18>=Aannames!$B$24,Aannames!$B$26*(1+Aannames!$B$6)^(A18-Aannames!$B$24),0) -> 0 | E18: =C18+D18 -> 140 | F18: =E18*Aannames!$B$8 -> 63 | G18: =CohortBear!L$38 -> 140.544 | H18: =G18*Aannames!$B$9 -> 1.40544 | I18: =H18*Aannames!$B$10*(1-Aannames!$B$11) -> 5.3638618 | J18: =MIN(J17*(1-Aannames!$B$18)+IF(A18>=Aannames!$B$14,Aannames!$B$15*Aannames!$B$16,0),(Aannames!$B$19+IF(A18>=Aannames!$B$24,Aannames!$B$25,0))*Aannames!$B$20) -> 2.0538 | K18: =J18*Aannames!$B$17 -> 80.0982 | L18: =IF(AND(A18>12,MOD(A18-1,12)=0),Aannames!$B$37,0) -> 0 | M18: =I18+K18+L18 -> 85.462062 | N18: =Aannames!$B$28+G18*Aannames!$B$29 -> 62.81088 | O18: =Aannames!$B$30*(1+IF(A18>=Aannames!$B$24,1,0)) -> 80 | P18: =Aannames!$B$31 -> 70 | Q18: =IF(MOD(A18-1,12)=0,Aannames!$B$32,0) -> 0 | R18: =Aannames!$B$33+IF(MOD(A18-1,12)=0,Aannames!$B$34,0) -> 50 | S18: =IF(A18=1,Aannames!$B$35,0) -> 0 | T18: =SUM(N18:S18) -> 262.81088 | U18: =M18-T18 -> -177.34882 | V18: =V17+U18 -> -3519.5403
A19: 12 | B19: aug-27 | C19: =Aannames!$B$5*(1+Aannames!$B$6)^(A19-2)*(1+IF(MOD(A19-1,12)=0,Aannames!$B$7,0)) -> 140 | D19: =IF(A19>=Aannames!$B$24,Aannames!$B$26*(1+Aannames!$B$6)^(A19-Aannames!$B$24),0) -> 0 | E19: =C19+D19 -> 140 | F19: =E19*Aannames!$B$8 -> 63 | G19: =CohortBear!M$38 -> 143.271 | H19: =G19*Aannames!$B$9 -> 1.43271 | I19: =H19*Aannames!$B$10*(1-Aannames!$B$11) -> 5.4679377 | J19: =MIN(J18*(1-Aannames!$B$18)+IF(A19>=Aannames!$B$14,Aannames!$B$15*Aannames!$B$16,0),(Aannames!$B$19+IF(A19>=Aannames!$B$24,Aannames!$B$25,0))*Aannames!$B$20) -> 2.67111 | K19: =J19*Aannames!$B$17 -> 104.17329 | L19: =IF(AND(A19>12,MOD(A19-1,12)=0),Aannames!$B$37,0) -> 0 | M19: =I19+K19+L19 -> 109.64123 | N19: =Aannames!$B$28+G19*Aannames!$B$29 -> 62.86542 | O19: =Aannames!$B$30*(1+IF(A19>=Aannames!$B$24,1,0)) -> 80 | P19: =Aannames!$B$31 -> 70 | Q19: =IF(MOD(A19-1,12)=0,Aannames!$B$32,0) -> 0 | R19: =Aannames!$B$33+IF(MOD(A19-1,12)=0,Aannames!$B$34,0) -> 50 | S19: =IF(A19=1,Aannames!$B$35,0) -> 0 | T19: =SUM(N19:S19) -> 262.86542 | U19: =M19-T19 -> -153.22419 | V19: =V18+U19 -> -3672.7645
A20: 13 | B20: sep-27 | C20: =Aannames!$B$5*(1+Aannames!$B$6)^(A20-2)*(1+IF(MOD(A20-1,12)=0,Aannames!$B$7,0)) -> 252 | D20: =IF(A20>=Aannames!$B$24,Aannames!$B$26*(1+Aannames!$B$6)^(A20-Aannames!$B$24),0) -> 0 | E20: =C20+D20 -> 252 | F20: =E20*Aannames!$B$8 -> 113.4 | G20: =CohortBear!N$38 -> 196.209 | H20: =G20*Aannames!$B$9 -> 1.96209 | I20: =H20*Aannames!$B$10*(1-Aannames!$B$11) -> 7.4883165 | J20: =MIN(J19*(1-Aannames!$B$18)+IF(A20>=Aannames!$B$14,Aannames!$B$15*Aannames!$B$16,0),(Aannames!$B$19+IF(A20>=Aannames!$B$24,Aannames!$B$25,0))*Aannames!$B$20) -> 3.2575545 | K20: =J20*Aannames!$B$17 -> 127.04463 | L20: =IF(AND(A20>12,MOD(A20-1,12)=0),Aannames!$B$37,0) -> 0 | M20: =I20+K20+L20 -> 134.53294 | N20: =Aannames!$B$28+G20*Aannames!$B$29 -> 63.92418 | O20: =Aannames!$B$30*(1+IF(A20>=Aannames!$B$24,1,0)) -> 80 | P20: =Aannames!$B$31 -> 70 | Q20: =IF(MOD(A20-1,12)=0,Aannames!$B$32,0) -> 150 | R20: =Aannames!$B$33+IF(MOD(A20-1,12)=0,Aannames!$B$34,0) -> 350 | S20: =IF(A20=1,Aannames!$B$35,0) -> 0 | T20: =SUM(N20:S20) -> 713.92418 | U20: =M20-T20 -> -579.39124 | V20: =V19+U20 -> -4252.1558
A21: 14 | B21: okt-27 | C21: =Aannames!$B$5*(1+Aannames!$B$6)^(A21-2)*(1+IF(MOD(A21-1,12)=0,Aannames!$B$7,0)) -> 140 | D21: =IF(A21>=Aannames!$B$24,Aannames!$B$26*(1+Aannames!$B$6)^(A21-Aannames!$B$24),0) -> 0 | E21: =C21+D21 -> 140 | F21: =E21*Aannames!$B$8 -> 63 | G21: =CohortBear!O$38 -> 162.495 | H21: =G21*Aannames!$B$9 -> 1.62495 | I21: =H21*Aannames!$B$10*(1-Aannames!$B$11) -> 6.2016217 | J21: =MIN(J20*(1-Aannames!$B$18)+IF(A21>=Aannames!$B$14,Aannames!$B$15*Aannames!$B$16,0),(Aannames!$B$19+IF(A21>=Aannames!$B$24,Aannames!$B$25,0))*Aannames!$B$20) -> 3.8146768 | K21: =J21*Aannames!$B$17 -> 148.77239 | L21: =IF(AND(A21>12,MOD(A21-1,12)=0),Aannames!$B$37,0) -> 0 | M21: =I21+K21+L21 -> 154.97402 | N21: =Aannames!$B$28+G21*Aannames!$B$29 -> 63.2499 | O21: =Aannames!$B$30*(1+IF(A21>=Aannames!$B$24,1,0)) -> 80 | P21: =Aannames!$B$31 -> 70 | Q21: =IF(MOD(A21-1,12)=0,Aannames!$B$32,0) -> 0 | R21: =Aannames!$B$33+IF(MOD(A21-1,12)=0,Aannames!$B$34,0) -> 50 | S21: =IF(A21=1,Aannames!$B$35,0) -> 0 | T21: =SUM(N21:S21) -> 263.2499 | U21: =M21-T21 -> -108.27588 | V21: =V20+U21 -> -4360.4316
A22: 15 | B22: nov-27 | C22: =Aannames!$B$5*(1+Aannames!$B$6)^(A22-2)*(1+IF(MOD(A22-1,12)=0,Aannames!$B$7,0)) -> 140 | D22: =IF(A22>=Aannames!$B$24,Aannames!$B$26*(1+Aannames!$B$6)^(A22-Aannames!$B$24),0) -> 0 | E22: =C22+D22 -> 140 | F22: =E22*Aannames!$B$8 -> 63 | G22: =CohortBear!P$38 -> 159.903 | H22: =G22*Aannames!$B$9 -> 1.59903 | I22: =H22*Aannames!$B$10*(1-Aannames!$B$11) -> 6.102698 | J22: =MIN(J21*(1-Aannames!$B$18)+IF(A22>=Aannames!$B$14,Aannames!$B$15*Aannames!$B$16,0),(Aannames!$B$19+IF(A22>=Aannames!$B$24,Aannames!$B$25,0))*Aannames!$B$20) -> 4.3439429 | K22: =J22*Aannames!$B$17 -> 169.41377 | L22: =IF(AND(A22>12,MOD(A22-1,12)=0),Aannames!$B$37,0) -> 0 | M22: =I22+K22+L22 -> 175.51647 | N22: =Aannames!$B$28+G22*Aannames!$B$29 -> 63.19806 | O22: =Aannames!$B$30*(1+IF(A22>=Aannames!$B$24,1,0)) -> 80 | P22: =Aannames!$B$31 -> 70 | Q22: =IF(MOD(A22-1,12)=0,Aannames!$B$32,0) -> 0 | R22: =Aannames!$B$33+IF(MOD(A22-1,12)=0,Aannames!$B$34,0) -> 50 | S22: =IF(A22=1,Aannames!$B$35,0) -> 0 | T22: =SUM(N22:S22) -> 263.19806 | U22: =M22-T22 -> -87.681587 | V22: =V21+U22 -> -4448.1132
A23: 16 | B23: dec-27 | C23: =Aannames!$B$5*(1+Aannames!$B$6)^(A23-2)*(1+IF(MOD(A23-1,12)=0,Aannames!$B$7,0)) -> 140 | D23: =IF(A23>=Aannames!$B$24,Aannames!$B$26*(1+Aannames!$B$6)^(A23-Aannames!$B$24),0) -> 0 | E23: =C23+D23 -> 140 | F23: =E23*Aannames!$B$8 -> 63 | G23: =CohortBear!Q$38 -> 159.93 | H23: =G23*Aannames!$B$9 -> 1.5993 | I23: =H23*Aannames!$B$10*(1-Aannames!$B$11) -> 6.1037285 | J23: =MIN(J22*(1-Aannames!$B$18)+IF(A23>=Aannames!$B$14,Aannames!$B$15*Aannames!$B$16,0),(Aannames!$B$19+IF(A23>=Aannames!$B$24,Aannames!$B$25,0))*Aannames!$B$20) -> 4.8467458 | K23: =J23*Aannames!$B$17 -> 189.02309 | L23: =IF(AND(A23>12,MOD(A23-1,12)=0),Aannames!$B$37,0) -> 0 | M23: =I23+K23+L23 -> 195.12681 | N23: =Aannames!$B$28+G23*Aannames!$B$29 -> 63.1986 | O23: =Aannames!$B$30*(1+IF(A23>=Aannames!$B$24,1,0)) -> 80 | P23: =Aannames!$B$31 -> 70 | Q23: =IF(MOD(A23-1,12)=0,Aannames!$B$32,0) -> 0 | R23: =Aannames!$B$33+IF(MOD(A23-1,12)=0,Aannames!$B$34,0) -> 50 | S23: =IF(A23=1,Aannames!$B$35,0) -> 0 | T23: =SUM(N23:S23) -> 263.1986 | U23: =M23-T23 -> -68.071786 | V23: =V22+U23 -> -4516.185
A24: 17 | B24: jan-28 | C24: =Aannames!$B$5*(1+Aannames!$B$6)^(A24-2)*(1+IF(MOD(A24-1,12)=0,Aannames!$B$7,0)) -> 140 | D24: =IF(A24>=Aannames!$B$24,Aannames!$B$26*(1+Aannames!$B$6)^(A24-Aannames!$B$24),0) -> 0 | E24: =C24+D24 -> 140 | F24: =E24*Aannames!$B$8 -> 63 | G24: =CohortBear!R$38 -> 160.902 | H24: =G24*Aannames!$B$9 -> 1.60902 | I24: =H24*Aannames!$B$10*(1-Aannames!$B$11) -> 6.1408248 | J24: =MIN(J23*(1-Aannames!$B$18)+IF(A24>=Aannames!$B$14,Aannames!$B$15*Aannames!$B$16,0),(Aannames!$B$19+IF(A24>=Aannames!$B$24,Aannames!$B$25,0))*Aannames!$B$20) -> 5.3244085 | K24: =J24*Aannames!$B$17 -> 207.65193 | L24: =IF(AND(A24>12,MOD(A24-1,12)=0),Aannames!$B$37,0) -> 0 | M24: =I24+K24+L24 -> 213.79276 | N24: =Aannames!$B$28+G24*Aannames!$B$29 -> 63.21804 | O24: =Aannames!$B$30*(1+IF(A24>=Aannames!$B$24,1,0)) -> 80 | P24: =Aannames!$B$31 -> 70 | Q24: =IF(MOD(A24-1,12)=0,Aannames!$B$32,0) -> 0 | R24: =Aannames!$B$33+IF(MOD(A24-1,12)=0,Aannames!$B$34,0) -> 50 | S24: =IF(A24=1,Aannames!$B$35,0) -> 0 | T24: =SUM(N24:S24) -> 263.21804 | U24: =M24-T24 -> -49.425284 | V24: =V23+U24 -> -4565.6103
A25: 18 | B25: feb-28 | C25: =Aannames!$B$5*(1+Aannames!$B$6)^(A25-2)*(1+IF(MOD(A25-1,12)=0,Aannames!$B$7,0)) -> 140 | D25: =IF(A25>=Aannames!$B$24,Aannames!$B$26*(1+Aannames!$B$6)^(A25-Aannames!$B$24),0) -> 0 | E25: =C25+D25 -> 140 | F25: =E25*Aannames!$B$8 -> 63 | G25: =CohortBear!S$38 -> 162.567 | H25: =G25*Aannames!$B$9 -> 1.62567 | I25: =H25*Aannames!$B$10*(1-Aannames!$B$11) -> 6.2043696 | J25: =MIN(J24*(1-Aannames!$B$18)+IF(A25>=Aannames!$B$14,Aannames!$B$15*Aannames!$B$16,0),(Aannames!$B$19+IF(A25>=Aannames!$B$24,Aannames!$B$25,0))*Aannames!$B$20) -> 5.7781881 | K25: =J25*Aannames!$B$17 -> 225.34933 | L25: =IF(AND(A25>12,MOD(A25-1,12)=0),Aannames!$B$37,0) -> 0 | M25: =I25+K25+L25 -> 231.5537 | N25: =Aannames!$B$28+G25*Aannames!$B$29 -> 63.25134 | O25: =Aannames!$B$30*(1+IF(A25>=Aannames!$B$24,1,0)) -> 80 | P25: =Aannames!$B$31 -> 70 | Q25: =IF(MOD(A25-1,12)=0,Aannames!$B$32,0) -> 0 | R25: =Aannames!$B$33+IF(MOD(A25-1,12)=0,Aannames!$B$34,0) -> 50 | S25: =IF(A25=1,Aannames!$B$35,0) -> 0 | T25: =SUM(N25:S25) -> 263.25134 | U25: =M25-T25 -> -31.697636 | V25: =V24+U25 -> -4597.3079
A26: 19 | B26: mrt-28 | C26: =Aannames!$B$5*(1+Aannames!$B$6)^(A26-2)*(1+IF(MOD(A26-1,12)=0,Aannames!$B$7,0)) -> 140 | D26: =IF(A26>=Aannames!$B$24,Aannames!$B$26*(1+Aannames!$B$6)^(A26-Aannames!$B$24),0) -> 0 | E26: =C26+D26 -> 140 | F26: =E26*Aannames!$B$8 -> 63 | G26: =CohortBear!T$38 -> 164.421 | H26: =G26*Aannames!$B$9 -> 1.64421 | I26: =H26*Aannames!$B$10*(1-Aannames!$B$11) -> 6.2751275 | J26: =MIN(J25*(1-Aannames!$B$18)+IF(A26>=Aannames!$B$14,Aannames!$B$15*Aannames!$B$16,0),(Aannames!$B$19+IF(A26>=Aannames!$B$24,Aannames!$B$25,0))*Aannames!$B$20) -> 6.2092787 | K26: =J26*Aannames!$B$17 -> 242.16187 | L26: =IF(AND(A26>12,MOD(A26-1,12)=0),Aannames!$B$37,0) -> 0 | M26: =I26+K26+L26 -> 248.437 | N26: =Aannames!$B$28+G26*Aannames!$B$29 -> 63.28842 | O26: =Aannames!$B$30*(1+IF(A26>=Aannames!$B$24,1,0)) -> 80 | P26: =Aannames!$B$31 -> 70 | Q26: =IF(MOD(A26-1,12)=0,Aannames!$B$32,0) -> 0 | R26: =Aannames!$B$33+IF(MOD(A26-1,12)=0,Aannames!$B$34,0) -> 50 | S26: =IF(A26=1,Aannames!$B$35,0) -> 0 | T26: =SUM(N26:S26) -> 263.28842 | U26: =M26-T26 -> -14.851424 | V26: =V25+U26 -> -4612.1594
A27: 20 | B27: apr-28 | C27: =Aannames!$B$5*(1+Aannames!$B$6)^(A27-2)*(1+IF(MOD(A27-1,12)=0,Aannames!$B$7,0)) -> 140 | D27: =IF(A27>=Aannames!$B$24,Aannames!$B$26*(1+Aannames!$B$6)^(A27-Aannames!$B$24),0) -> 0 | E27: =C27+D27 -> 140 | F27: =E27*Aannames!$B$8 -> 63 | G27: =CohortBear!U$38 -> 166.3632 | H27: =G27*Aannames!$B$9 -> 1.663632 | I27: =H27*Aannames!$B$10*(1-Aannames!$B$11) -> 6.3492515 | J27: =MIN(J26*(1-Aannames!$B$18)+IF(A27>=Aannames!$B$14,Aannames!$B$15*Aannames!$B$16,0),(Aannames!$B$19+IF(A27>=Aannames!$B$24,Aannames!$B$25,0))*Aannames!$B$20) -> 6.6188147 | K27: =J27*Aannames!$B$17 -> 258.13377 | L27: =IF(AND(A27>12,MOD(A27-1,12)=0),Aannames!$B$37,0) -> 0 | M27: =I27+K27+L27 -> 264.48303 | N27: =Aannames!$B$28+G27*Aannames!$B$29 -> 63.327264 | O27: =Aannames!$B$30*(1+IF(A27>=Aannames!$B$24,1,0)) -> 80 | P27: =Aannames!$B$31 -> 70 | Q27: =IF(MOD(A27-1,12)=0,Aannames!$B$32,0) -> 0 | R27: =Aannames!$B$33+IF(MOD(A27-1,12)=0,Aannames!$B$34,0) -> 50 | S27: =IF(A27=1,Aannames!$B$35,0) -> 0 | T27: =SUM(N27:S27) -> 263.32726 | U27: =M27-T27 -> 1.1557623 | V27: =V26+U27 -> -4611.0036
A28: 21 | B28: mei-28 | C28: =Aannames!$B$5*(1+Aannames!$B$6)^(A28-2)*(1+IF(MOD(A28-1,12)=0,Aannames!$B$7,0)) -> 140 | D28: =IF(A28>=Aannames!$B$24,Aannames!$B$26*(1+Aannames!$B$6)^(A28-Aannames!$B$24),0) -> 0 | E28: =C28+D28 -> 140 | F28: =E28*Aannames!$B$8 -> 63 | G28: =CohortBear!V$38 -> 168.2928 | H28: =G28*Aannames!$B$9 -> 1.682928 | I28: =H28*Aannames!$B$10*(1-Aannames!$B$11) -> 6.4228947 | J28: =MIN(J27*(1-Aannames!$B$18)+IF(A28>=Aannames!$B$14,Aannames!$B$15*Aannames!$B$16,0),(Aannames!$B$19+IF(A28>=Aannames!$B$24,Aannames!$B$25,0))*Aannames!$B$20) -> 7.007874 | K28: =J28*Aannames!$B$17 -> 273.30709 | L28: =IF(AND(A28>12,MOD(A28-1,12)=0),Aannames!$B$37,0) -> 0 | M28: =I28+K28+L28 -> 279.72998 | N28: =Aannames!$B$28+G28*Aannames!$B$29 -> 63.365856 | O28: =Aannames!$B$30*(1+IF(A28>=Aannames!$B$24,1,0)) -> 80 | P28: =Aannames!$B$31 -> 70 | Q28: =IF(MOD(A28-1,12)=0,Aannames!$B$32,0) -> 0 | R28: =Aannames!$B$33+IF(MOD(A28-1,12)=0,Aannames!$B$34,0) -> 50 | S28: =IF(A28=1,Aannames!$B$35,0) -> 0 | T28: =SUM(N28:S28) -> 263.36586 | U28: =M28-T28 -> 16.364125 | V28: =V27+U28 -> -4594.6395
A29: 22 | B29: jun-28 | C29: =Aannames!$B$5*(1+Aannames!$B$6)^(A29-2)*(1+IF(MOD(A29-1,12)=0,Aannames!$B$7,0)) -> 140 | D29: =IF(A29>=Aannames!$B$24,Aannames!$B$26*(1+Aannames!$B$6)^(A29-Aannames!$B$24),0) -> 0 | E29: =C29+D29 -> 140 | F29: =E29*Aannames!$B$8 -> 63 | G29: =CohortBear!W$38 -> 170.2602 | H29: =G29*Aannames!$B$9 -> 1.702602 | I29: =H29*Aannames!$B$10*(1-Aannames!$B$11) -> 6.4979805 | J29: =MIN(J28*(1-Aannames!$B$18)+IF(A29>=Aannames!$B$14,Aannames!$B$15*Aannames!$B$16,0),(Aannames!$B$19+IF(A29>=Aannames!$B$24,Aannames!$B$25,0))*Aannames!$B$20) -> 7.3774803 | K29: =J29*Aannames!$B$17 -> 287.72173 | L29: =IF(AND(A29>12,MOD(A29-1,12)=0),Aannames!$B$37,0) -> 0 | M29: =I29+K29+L29 -> 294.21971 | N29: =Aannames!$B$28+G29*Aannames!$B$29 -> 63.405204 | O29: =Aannames!$B$30*(1+IF(A29>=Aannames!$B$24,1,0)) -> 80 | P29: =Aannames!$B$31 -> 70 | Q29: =IF(MOD(A29-1,12)=0,Aannames!$B$32,0) -> 0 | R29: =Aannames!$B$33+IF(MOD(A29-1,12)=0,Aannames!$B$34,0) -> 50 | S29: =IF(A29=1,Aannames!$B$35,0) -> 0 | T29: =SUM(N29:S29) -> 263.4052 | U29: =M29-T29 -> 30.814508 | V29: =V28+U29 -> -4563.825
A30: 23 | B30: jul-28 | C30: =Aannames!$B$5*(1+Aannames!$B$6)^(A30-2)*(1+IF(MOD(A30-1,12)=0,Aannames!$B$7,0)) -> 140 | D30: =IF(A30>=Aannames!$B$24,Aannames!$B$26*(1+Aannames!$B$6)^(A30-Aannames!$B$24),0) -> 0 | E30: =C30+D30 -> 140 | F30: =E30*Aannames!$B$8 -> 63 | G30: =CohortBear!X$38 -> 172.1646 | H30: =G30*Aannames!$B$9 -> 1.721646 | I30: =H30*Aannames!$B$10*(1-Aannames!$B$11) -> 6.570662 | J30: =MIN(J29*(1-Aannames!$B$18)+IF(A30>=Aannames!$B$14,Aannames!$B$15*Aannames!$B$16,0),(Aannames!$B$19+IF(A30>=Aannames!$B$24,Aannames!$B$25,0))*Aannames!$B$20) -> 7.7286063 | K30: =J30*Aannames!$B$17 -> 301.41565 | L30: =IF(AND(A30>12,MOD(A30-1,12)=0),Aannames!$B$37,0) -> 0 | M30: =I30+K30+L30 -> 307.98631 | N30: =Aannames!$B$28+G30*Aannames!$B$29 -> 63.443292 | O30: =Aannames!$B$30*(1+IF(A30>=Aannames!$B$24,1,0)) -> 80 | P30: =Aannames!$B$31 -> 70 | Q30: =IF(MOD(A30-1,12)=0,Aannames!$B$32,0) -> 0 | R30: =Aannames!$B$33+IF(MOD(A30-1,12)=0,Aannames!$B$34,0) -> 50 | S30: =IF(A30=1,Aannames!$B$35,0) -> 0 | T30: =SUM(N30:S30) -> 263.44329 | U30: =M30-T30 -> 44.543015 | V30: =V29+U30 -> -4519.2819
A31: 24 | B31: aug-28 | C31: =Aannames!$B$5*(1+Aannames!$B$6)^(A31-2)*(1+IF(MOD(A31-1,12)=0,Aannames!$B$7,0)) -> 140 | D31: =IF(A31>=Aannames!$B$24,Aannames!$B$26*(1+Aannames!$B$6)^(A31-Aannames!$B$24),0) -> 0 | E31: =C31+D31 -> 140 | F31: =E31*Aannames!$B$8 -> 63 | G31: =CohortBear!Y$38 -> 174.0564 | H31: =G31*Aannames!$B$9 -> 1.740564 | I31: =H31*Aannames!$B$10*(1-Aannames!$B$11) -> 6.6428625 | J31: =MIN(J30*(1-Aannames!$B$18)+IF(A31>=Aannames!$B$14,Aannames!$B$15*Aannames!$B$16,0),(Aannames!$B$19+IF(A31>=Aannames!$B$24,Aannames!$B$25,0))*Aannames!$B$20) -> 8.062176 | K31: =J31*Aannames!$B$17 -> 314.42486 | L31: =IF(AND(A31>12,MOD(A31-1,12)=0),Aannames!$B$37,0) -> 0 | M31: =I31+K31+L31 -> 321.06773 | N31: =Aannames!$B$28+G31*Aannames!$B$29 -> 63.481128 | O31: =Aannames!$B$30*(1+IF(A31>=Aannames!$B$24,1,0)) -> 80 | P31: =Aannames!$B$31 -> 70 | Q31: =IF(MOD(A31-1,12)=0,Aannames!$B$32,0) -> 0 | R31: =Aannames!$B$33+IF(MOD(A31-1,12)=0,Aannames!$B$34,0) -> 50 | S31: =IF(A31=1,Aannames!$B$35,0) -> 0 | T31: =SUM(N31:S31) -> 263.48113 | U31: =M31-T31 -> 57.586597 | V31: =V30+U31 -> -4461.6953
A32: 25 | B32: sep-28 | C32: =Aannames!$B$5*(1+Aannames!$B$6)^(A32-2)*(1+IF(MOD(A32-1,12)=0,Aannames!$B$7,0)) -> 252 | D32: =IF(A32>=Aannames!$B$24,Aannames!$B$26*(1+Aannames!$B$6)^(A32-Aannames!$B$24),0) -> 0 | E32: =C32+D32 -> 252 | F32: =E32*Aannames!$B$8 -> 113.4 | G32: =CohortBear!Z$38 -> 226.2852 | H32: =G32*Aannames!$B$9 -> 2.262852 | I32: =H32*Aannames!$B$10*(1-Aannames!$B$11) -> 8.6361747 | J32: =MIN(J31*(1-Aannames!$B$18)+IF(A32>=Aannames!$B$14,Aannames!$B$15*Aannames!$B$16,0),(Aannames!$B$19+IF(A32>=Aannames!$B$24,Aannames!$B$25,0))*Aannames!$B$20) -> 8.3790672 | K32: =J32*Aannames!$B$17 -> 326.78362 | L32: =IF(AND(A32>12,MOD(A32-1,12)=0),Aannames!$B$37,0) -> 0 | M32: =I32+K32+L32 -> 335.41979 | N32: =Aannames!$B$28+G32*Aannames!$B$29 -> 64.525704 | O32: =Aannames!$B$30*(1+IF(A32>=Aannames!$B$24,1,0)) -> 80 | P32: =Aannames!$B$31 -> 70 | Q32: =IF(MOD(A32-1,12)=0,Aannames!$B$32,0) -> 150 | R32: =Aannames!$B$33+IF(MOD(A32-1,12)=0,Aannames!$B$34,0) -> 350 | S32: =IF(A32=1,Aannames!$B$35,0) -> 0 | T32: =SUM(N32:S32) -> 714.5257 | U32: =M32-T32 -> -379.10591 | V32: =V31+U32 -> -4840.8013
A33: 26 | B33: okt-28 | C33: =Aannames!$B$5*(1+Aannames!$B$6)^(A33-2)*(1+IF(MOD(A33-1,12)=0,Aannames!$B$7,0)) -> 140 | D33: =IF(A33>=Aannames!$B$24,Aannames!$B$26*(1+Aannames!$B$6)^(A33-Aannames!$B$24),0) -> 0 | E33: =C33+D33 -> 140 | F33: =E33*Aannames!$B$8 -> 63 | G33: =CohortBear!AA$38 -> 191.8134 | H33: =G33*Aannames!$B$9 -> 1.918134 | I33: =H33*Aannames!$B$10*(1-Aannames!$B$11) -> 7.3205584 | J33: =MIN(J32*(1-Aannames!$B$18)+IF(A33>=Aannames!$B$14,Aannames!$B$15*Aannames!$B$16,0),(Aannames!$B$19+IF(A33>=Aannames!$B$24,Aannames!$B$25,0))*Aannames!$B$20) -> 8.6801138 | K33: =J33*Aannames!$B$17 -> 338.52444 | L33: =IF(AND(A33>12,MOD(A33-1,12)=0),Aannames!$B$37,0) -> 0 | M33: =I33+K33+L33 -> 345.845 | N33: =Aannames!$B$28+G33*Aannames!$B$29 -> 63.836268 | O33: =Aannames!$B$30*(1+IF(A33>=Aannames!$B$24,1,0)) -> 80 | P33: =Aannames!$B$31 -> 70 | Q33: =IF(MOD(A33-1,12)=0,Aannames!$B$32,0) -> 0 | R33: =Aannames!$B$33+IF(MOD(A33-1,12)=0,Aannames!$B$34,0) -> 50 | S33: =IF(A33=1,Aannames!$B$35,0) -> 0 | T33: =SUM(N33:S33) -> 263.83627 | U33: =M33-T33 -> 82.008729 | V33: =V32+U33 -> -4758.7925
A34: 27 | B34: nov-28 | C34: =Aannames!$B$5*(1+Aannames!$B$6)^(A34-2)*(1+IF(MOD(A34-1,12)=0,Aannames!$B$7,0)) -> 140 | D34: =IF(A34>=Aannames!$B$24,Aannames!$B$26*(1+Aannames!$B$6)^(A34-Aannames!$B$24),0) -> 0 | E34: =C34+D34 -> 140 | F34: =E34*Aannames!$B$8 -> 63 | G34: =CohortBear!AB$38 -> 188.5266 | H34: =G34*Aannames!$B$9 -> 1.885266 | I34: =H34*Aannames!$B$10*(1-Aannames!$B$11) -> 7.1951177 | J34: =MIN(J33*(1-Aannames!$B$18)+IF(A34>=Aannames!$B$14,Aannames!$B$15*Aannames!$B$16,0),(Aannames!$B$19+IF(A34>=Aannames!$B$24,Aannames!$B$25,0))*Aannames!$B$20) -> 8.9661081 | K34: =J34*Aannames!$B$17 -> 349.67822 | L34: =IF(AND(A34>12,MOD(A34-1,12)=0),Aannames!$B$37,0) -> 0 | M34: =I34+K34+L34 -> 356.87333 | N34: =Aannames!$B$28+G34*Aannames!$B$29 -> 63.770532 | O34: =Aannames!$B$30*(1+IF(A34>=Aannames!$B$24,1,0)) -> 80 | P34: =Aannames!$B$31 -> 70 | Q34: =IF(MOD(A34-1,12)=0,Aannames!$B$32,0) -> 0 | R34: =Aannames!$B$33+IF(MOD(A34-1,12)=0,Aannames!$B$34,0) -> 50 | S34: =IF(A34=1,Aannames!$B$35,0) -> 0 | T34: =SUM(N34:S34) -> 263.77053 | U34: =M34-T34 -> 93.102803 | V34: =V33+U34 -> -4665.6897
A35: 28 | B35: dec-28 | C35: =Aannames!$B$5*(1+Aannames!$B$6)^(A35-2)*(1+IF(MOD(A35-1,12)=0,Aannames!$B$7,0)) -> 140 | D35: =IF(A35>=Aannames!$B$24,Aannames!$B$26*(1+Aannames!$B$6)^(A35-Aannames!$B$24),0) -> 0 | E35: =C35+D35 -> 140 | F35: =E35*Aannames!$B$8 -> 63 | G35: =CohortBear!AC$38 -> 187.7472 | H35: =G35*Aannames!$B$9 -> 1.877472 | I35: =H35*Aannames!$B$10*(1-Aannames!$B$11) -> 7.1653719 | J35: =MIN(J34*(1-Aannames!$B$18)+IF(A35>=Aannames!$B$14,Aannames!$B$15*Aannames!$B$16,0),(Aannames!$B$19+IF(A35>=Aannames!$B$24,Aannames!$B$25,0))*Aannames!$B$20) -> 9.2378027 | K35: =J35*Aannames!$B$17 -> 360.27431 | L35: =IF(AND(A35>12,MOD(A35-1,12)=0),Aannames!$B$37,0) -> 0 | M35: =I35+K35+L35 -> 367.43968 | N35: =Aannames!$B$28+G35*Aannames!$B$29 -> 63.754944 | O35: =Aannames!$B$30*(1+IF(A35>=Aannames!$B$24,1,0)) -> 80 | P35: =Aannames!$B$31 -> 70 | Q35: =IF(MOD(A35-1,12)=0,Aannames!$B$32,0) -> 0 | R35: =Aannames!$B$33+IF(MOD(A35-1,12)=0,Aannames!$B$34,0) -> 50 | S35: =IF(A35=1,Aannames!$B$35,0) -> 0 | T35: =SUM(N35:S35) -> 263.75494 | U35: =M35-T35 -> 103.68473 | V35: =V34+U35 -> -4562.005
A36: 29 | B36: jan-29 | C36: =Aannames!$B$5*(1+Aannames!$B$6)^(A36-2)*(1+IF(MOD(A36-1,12)=0,Aannames!$B$7,0)) -> 140 | D36: =IF(A36>=Aannames!$B$24,Aannames!$B$26*(1+Aannames!$B$6)^(A36-Aannames!$B$24),0) -> 0 | E36: =C36+D36 -> 140 | F36: =E36*Aannames!$B$8 -> 63 | G36: =CohortBear!AD$38 -> 187.9128 | H36: =G36*Aannames!$B$9 -> 1.879128 | I36: =H36*Aannames!$B$10*(1-Aannames!$B$11) -> 7.171692 | J36: =MIN(J35*(1-Aannames!$B$18)+IF(A36>=Aannames!$B$14,Aannames!$B$15*Aannames!$B$16,0),(Aannames!$B$19+IF(A36>=Aannames!$B$24,Aannames!$B$25,0))*Aannames!$B$20) -> 9.4959126 | K36: =J36*Aannames!$B$17 -> 370.34059 | L36: =IF(AND(A36>12,MOD(A36-1,12)=0),Aannames!$B$37,0) -> 0 | M36: =I36+K36+L36 -> 377.51228 | N36: =Aannames!$B$28+G36*Aannames!$B$29 -> 63.758256 | O36: =Aannames!$B$30*(1+IF(A36>=Aannames!$B$24,1,0)) -> 80 | P36: =Aannames!$B$31 -> 70 | Q36: =IF(MOD(A36-1,12)=0,Aannames!$B$32,0) -> 0 | R36: =Aannames!$B$33+IF(MOD(A36-1,12)=0,Aannames!$B$34,0) -> 50 | S36: =IF(A36=1,Aannames!$B$35,0) -> 0 | T36: =SUM(N36:S36) -> 263.75826 | U36: =M36-T36 -> 113.75403 | V36: =V35+U36 -> -4448.251
A37: 30 | B37: feb-29 | C37: =Aannames!$B$5*(1+Aannames!$B$6)^(A37-2)*(1+IF(MOD(A37-1,12)=0,Aannames!$B$7,0)) -> 140 | D37: =IF(A37>=Aannames!$B$24,Aannames!$B$26*(1+Aannames!$B$6)^(A37-Aannames!$B$24),0) -> 0 | E37: =C37+D37 -> 140 | F37: =E37*Aannames!$B$8 -> 63 | G37: =CohortBear!AE$38 -> 188.9964 | H37: =G37*Aannames!$B$9 -> 1.889964 | I37: =H37*Aannames!$B$10*(1-Aannames!$B$11) -> 7.2130476 | J37: =MIN(J36*(1-Aannames!$B$18)+IF(A37>=Aannames!$B$14,Aannames!$B$15*Aannames!$B$16,0),(Aannames!$B$19+IF(A37>=Aannames!$B$24,Aannames!$B$25,0))*Aannames!$B$20) -> 9.741117 | K37: =J37*Aannames!$B$17 -> 379.90356 | L37: =IF(AND(A37>12,MOD(A37-1,12)=0),Aannames!$B$37,0) -> 0 | M37: =I37+K37+L37 -> 387.11661 | N37: =Aannames!$B$28+G37*Aannames!$B$29 -> 63.779928 | O37: =Aannames!$B$30*(1+IF(A37>=Aannames!$B$24,1,0)) -> 80 | P37: =Aannames!$B$31 -> 70 | Q37: =IF(MOD(A37-1,12)=0,Aannames!$B$32,0) -> 0 | R37: =Aannames!$B$33+IF(MOD(A37-1,12)=0,Aannames!$B$34,0) -> 50 | S37: =IF(A37=1,Aannames!$B$35,0) -> 0 | T37: =SUM(N37:S37) -> 263.77993 | U37: =M37-T37 -> 123.33668 | V37: =V36+U37 -> -4324.9143
A38: 31 | B38: mrt-29 | C38: =Aannames!$B$5*(1+Aannames!$B$6)^(A38-2)*(1+IF(MOD(A38-1,12)=0,Aannames!$B$7,0)) -> 140 | D38: =IF(A38>=Aannames!$B$24,Aannames!$B$26*(1+Aannames!$B$6)^(A38-Aannames!$B$24),0) -> 0 | E38: =C38+D38 -> 140 | F38: =E38*Aannames!$B$8 -> 63 | G38: =CohortBear!AF$38 -> 190.107 | H38: =G38*Aannames!$B$9 -> 1.90107 | I38: =H38*Aannames!$B$10*(1-Aannames!$B$11) -> 7.2554337 | J38: =MIN(J37*(1-Aannames!$B$18)+IF(A38>=Aannames!$B$14,Aannames!$B$15*Aannames!$B$16,0),(Aannames!$B$19+IF(A38>=Aannames!$B$24,Aannames!$B$25,0))*Aannames!$B$20) -> 9.9740611 | K38: =J38*Aannames!$B$17 -> 388.98838 | L38: =IF(AND(A38>12,MOD(A38-1,12)=0),Aannames!$B$37,0) -> 0 | M38: =I38+K38+L38 -> 396.24382 | N38: =Aannames!$B$28+G38*Aannames!$B$29 -> 63.80214 | O38: =Aannames!$B$30*(1+IF(A38>=Aannames!$B$24,1,0)) -> 80 | P38: =Aannames!$B$31 -> 70 | Q38: =IF(MOD(A38-1,12)=0,Aannames!$B$32,0) -> 0 | R38: =Aannames!$B$33+IF(MOD(A38-1,12)=0,Aannames!$B$34,0) -> 50 | S38: =IF(A38=1,Aannames!$B$35,0) -> 0 | T38: =SUM(N38:S38) -> 263.80214 | U38: =M38-T38 -> 132.44168 | V38: =V37+U38 -> -4192.4726
A39: 32 | B39: apr-29 | C39: =Aannames!$B$5*(1+Aannames!$B$6)^(A39-2)*(1+IF(MOD(A39-1,12)=0,Aannames!$B$7,0)) -> 140 | D39: =IF(A39>=Aannames!$B$24,Aannames!$B$26*(1+Aannames!$B$6)^(A39-Aannames!$B$24),0) -> 0 | E39: =C39+D39 -> 140 | F39: =E39*Aannames!$B$8 -> 63 | G39: =CohortBear!AG$38 -> 191.5308 | H39: =G39*Aannames!$B$9 -> 1.915308 | I39: =H39*Aannames!$B$10*(1-Aannames!$B$11) -> 7.309773 | J39: =MIN(J38*(1-Aannames!$B$18)+IF(A39>=Aannames!$B$14,Aannames!$B$15*Aannames!$B$16,0),(Aannames!$B$19+IF(A39>=Aannames!$B$24,Aannames!$B$25,0))*Aannames!$B$20) -> 10.195358 | K39: =J39*Aannames!$B$17 -> 397.61896 | L39: =IF(AND(A39>12,MOD(A39-1,12)=0),Aannames!$B$37,0) -> 0 | M39: =I39+K39+L39 -> 404.92874 | N39: =Aannames!$B$28+G39*Aannames!$B$29 -> 63.830616 | O39: =Aannames!$B$30*(1+IF(A39>=Aannames!$B$24,1,0)) -> 80 | P39: =Aannames!$B$31 -> 70 | Q39: =IF(MOD(A39-1,12)=0,Aannames!$B$32,0) -> 0 | R39: =Aannames!$B$33+IF(MOD(A39-1,12)=0,Aannames!$B$34,0) -> 50 | S39: =IF(A39=1,Aannames!$B$35,0) -> 0 | T39: =SUM(N39:S39) -> 263.83062 | U39: =M39-T39 -> 141.09812 | V39: =V38+U39 -> -4051.3745
A40: 33 | B40: mei-29 | C40: =Aannames!$B$5*(1+Aannames!$B$6)^(A40-2)*(1+IF(MOD(A40-1,12)=0,Aannames!$B$7,0)) -> 140 | D40: =IF(A40>=Aannames!$B$24,Aannames!$B$26*(1+Aannames!$B$6)^(A40-Aannames!$B$24),0) -> 0 | E40: =C40+D40 -> 140 | F40: =E40*Aannames!$B$8 -> 63 | G40: =CohortBear!AH$38 -> 192.78 | H40: =G40*Aannames!$B$9 -> 1.9278 | I40: =H40*Aannames!$B$10*(1-Aannames!$B$11) -> 7.3574487 | J40: =MIN(J39*(1-Aannames!$B$18)+IF(A40>=Aannames!$B$14,Aannames!$B$15*Aannames!$B$16,0),(Aannames!$B$19+IF(A40>=Aannames!$B$24,Aannames!$B$25,0))*Aannames!$B$20) -> 10.40559 | K40: =J40*Aannames!$B$17 -> 405.81802 | L40: =IF(AND(A40>12,MOD(A40-1,12)=0),Aannames!$B$37,0) -> 0 | M40: =I40+K40+L40 -> 413.17546 | N40: =Aannames!$B$28+G40*Aannames!$B$29 -> 63.8556 | O40: =Aannames!$B$30*(1+IF(A40>=Aannames!$B$24,1,0)) -> 80 | P40: =Aannames!$B$31 -> 70 | Q40: =IF(MOD(A40-1,12)=0,Aannames!$B$32,0) -> 0 | R40: =Aannames!$B$33+IF(MOD(A40-1,12)=0,Aannames!$B$34,0) -> 50 | S40: =IF(A40=1,Aannames!$B$35,0) -> 0 | T40: =SUM(N40:S40) -> 263.8556 | U40: =M40-T40 -> 149.31986 | V40: =V39+U40 -> -3902.0546
A41: 34 | B41: jun-29 | C41: =Aannames!$B$5*(1+Aannames!$B$6)^(A41-2)*(1+IF(MOD(A41-1,12)=0,Aannames!$B$7,0)) -> 140 | D41: =IF(A41>=Aannames!$B$24,Aannames!$B$26*(1+Aannames!$B$6)^(A41-Aannames!$B$24),0) -> 0 | E41: =C41+D41 -> 140 | F41: =E41*Aannames!$B$8 -> 63 | G41: =CohortBear!AI$38 -> 194.292 | H41: =G41*Aannames!$B$9 -> 1.94292 | I41: =H41*Aannames!$B$10*(1-Aannames!$B$11) -> 7.4151542 | J41: =MIN(J40*(1-Aannames!$B$18)+IF(A41>=Aannames!$B$14,Aannames!$B$15*Aannames!$B$16,0),(Aannames!$B$19+IF(A41>=Aannames!$B$24,Aannames!$B$25,0))*Aannames!$B$20) -> 10.605311 | K41: =J41*Aannames!$B$17 -> 413.60711 | L41: =IF(AND(A41>12,MOD(A41-1,12)=0),Aannames!$B$37,0) -> 0 | M41: =I41+K41+L41 -> 421.02227 | N41: =Aannames!$B$28+G41*Aannames!$B$29 -> 63.88584 | O41: =Aannames!$B$30*(1+IF(A41>=Aannames!$B$24,1,0)) -> 80 | P41: =Aannames!$B$31 -> 70 | Q41: =IF(MOD(A41-1,12)=0,Aannames!$B$32,0) -> 0 | R41: =Aannames!$B$33+IF(MOD(A41-1,12)=0,Aannames!$B$34,0) -> 50 | S41: =IF(A41=1,Aannames!$B$35,0) -> 0 | T41: =SUM(N41:S41) -> 263.88584 | U41: =M41-T41 -> 157.13643 | V41: =V40+U41 -> -3744.9182
A42: 35 | B42: jul-29 | C42: =Aannames!$B$5*(1+Aannames!$B$6)^(A42-2)*(1+IF(MOD(A42-1,12)=0,Aannames!$B$7,0)) -> 140 | D42: =IF(A42>=Aannames!$B$24,Aannames!$B$26*(1+Aannames!$B$6)^(A42-Aannames!$B$24),0) -> 0 | E42: =C42+D42 -> 140 | F42: =E42*Aannames!$B$8 -> 63 | G42: =CohortBear!AJ$38 -> 195.579 | H42: =G42*Aannames!$B$9 -> 1.95579 | I42: =H42*Aannames!$B$10*(1-Aannames!$B$11) -> 7.4642725 | J42: =MIN(J41*(1-Aannames!$B$18)+IF(A42>=Aannames!$B$14,Aannames!$B$15*Aannames!$B$16,0),(Aannames!$B$19+IF(A42>=Aannames!$B$24,Aannames!$B$25,0))*Aannames!$B$20) -> 10.795045 | K42: =J42*Aannames!$B$17 -> 421.00676 | L42: =IF(AND(A42>12,MOD(A42-1,12)=0),Aannames!$B$37,0) -> 0 | M42: =I42+K42+L42 -> 428.47103 | N42: =Aannames!$B$28+G42*Aannames!$B$29 -> 63.91158 | O42: =Aannames!$B$30*(1+IF(A42>=Aannames!$B$24,1,0)) -> 80 | P42: =Aannames!$B$31 -> 70 | Q42: =IF(MOD(A42-1,12)=0,Aannames!$B$32,0) -> 0 | R42: =Aannames!$B$33+IF(MOD(A42-1,12)=0,Aannames!$B$34,0) -> 50 | S42: =IF(A42=1,Aannames!$B$35,0) -> 0 | T42: =SUM(N42:S42) -> 263.91158 | U42: =M42-T42 -> 164.55945 | V42: =V41+U42 -> -3580.3587
A43: 36 | B43: aug-29 | C43: =Aannames!$B$5*(1+Aannames!$B$6)^(A43-2)*(1+IF(MOD(A43-1,12)=0,Aannames!$B$7,0)) -> 140 | D43: =IF(A43>=Aannames!$B$24,Aannames!$B$26*(1+Aannames!$B$6)^(A43-Aannames!$B$24),0) -> 0 | E43: =C43+D43 -> 140 | F43: =E43*Aannames!$B$8 -> 63 | G43: =CohortBear!AK$38 -> 197.0784 | H43: =G43*Aannames!$B$9 -> 1.970784 | I43: =H43*Aannames!$B$10*(1-Aannames!$B$11) -> 7.5214971 | J43: =MIN(J42*(1-Aannames!$B$18)+IF(A43>=Aannames!$B$14,Aannames!$B$15*Aannames!$B$16,0),(Aannames!$B$19+IF(A43>=Aannames!$B$24,Aannames!$B$25,0))*Aannames!$B$20) -> 10.975293 | K43: =J43*Aannames!$B$17 -> 428.03642 | L43: =IF(AND(A43>12,MOD(A43-1,12)=0),Aannames!$B$37,0) -> 0 | M43: =I43+K43+L43 -> 435.55792 | N43: =Aannames!$B$28+G43*Aannames!$B$29 -> 63.941568 | O43: =Aannames!$B$30*(1+IF(A43>=Aannames!$B$24,1,0)) -> 80 | P43: =Aannames!$B$31 -> 70 | Q43: =IF(MOD(A43-1,12)=0,Aannames!$B$32,0) -> 0 | R43: =Aannames!$B$33+IF(MOD(A43-1,12)=0,Aannames!$B$34,0) -> 50 | S43: =IF(A43=1,Aannames!$B$35,0) -> 0 | T43: =SUM(N43:S43) -> 263.94157 | U43: =M43-T43 -> 171.61635 | V43: =V42+U43 -> -3408.7424
A45: KPI's
...

Sheet CohortBear
A1: Cohort \ kalendermaand | B1: 1 | C1: 2 | D1: 3 | E1: 4 | F1: 5 | G1: 6 | H1: 7 | I1: 8 | J1: 9 | K1: 10 | L1: 11 | M1: 12 | N1: 13 | O1: 14 | P1: 15 | Q1: 16 | R1: 17 | S1: 18 | T1: 19 | U1: 20 | V1: 21 | W1: 22 | X1: 23 | Y1: 24 | Z1: 25 | AA1: 26 | AB1: 27 | AC1: 28 | AD1: 29 | AE1: 30 | AF1: 31 | AG1: 32 | AH1: 33 | AI1: 34 | AJ1: 35 | AK1: 36
A2: 1 | B2: =ModelBear!$F$8*Retentie!$B$2 -> 225 | C2: =ModelBear!$F$8*Retentie!$B$3 -> 63 | D2: =ModelBear!$F$8*Retentie!$B$4 -> 40.5 | E2: =ModelBear!$F$8*Retentie!$B$5 -> 29.25 | F2: =ModelBear!$F$8*Retentie!$B$6 -> 22.5 | G2: =ModelBear!$F$8*Retentie!$B$7 -> 19.125 | H2: =ModelBear!$F$8*Retentie!$B$8 -> 16.875 | I2: =ModelBear!$F$8*Retentie!$B$9 -> 15.3 | J2: =ModelBear!$F$8*Retentie!$B$10 -> 13.95 | K2: =ModelBear!$F$8*Retentie!$B$11 -> 13.05 | L2: =ModelBear!$F$8*Retentie!$B$12 -> 12.15 | M2: =ModelBear!$F$8*Retentie!$B$13 -> 11.475 | N2: =ModelBear!$F$8*Retentie!$B$14 -> 10.8 | O2: =ModelBear!$F$8*Retentie!$B$15 -> 10.35 | P2: =ModelBear!$F$8*Retentie!$B$16 -> 9.9 | Q2: =ModelBear!$F$8*Retentie!$B$17 -> 9.675 | R2: =ModelBear!$F$8*Retentie!$B$18 -> 9.45 | S2: =ModelBear!$F$8*Retentie!$B$19 -> 9.225 | T2: =ModelBear!$F$8*Retentie!$B$20 -> 9 | U2: =ModelBear!$F$8*Retentie!$B$21 -> 8.775 | V2: =ModelBear!$F$8*Retentie!$B$22 -> 8.55 | W2: =ModelBear!$F$8*Retentie!$B$23 -> 8.325 | X2: =ModelBear!$F$8*Retentie!$B$24 -> 8.1 | Y2: =ModelBear!$F$8*Retentie!$B$25 -> 7.875 | Z2: =ModelBear!$F$8*Retentie!$B$26 -> 7.65 | AA2: =ModelBear!$F$8*Retentie!$B$27 -> 7.425 | AB2: =ModelBear!$F$8*Retentie!$B$28 -> 7.2 | AC2: =ModelBear!$F$8*Retentie!$B$29 -> 6.975 | AD2: =ModelBear!$F$8*Retentie!$B$30 -> 6.75 | AE2: =ModelBear!$F$8*Retentie!$B$31 -> 6.75 | AF2: =ModelBear!$F$8*Retentie!$B$32 -> 6.525 | AG2: =ModelBear!$F$8*Retentie!$B$33 -> 6.525 | AH2: =ModelBear!$F$8*Retentie!$B$34 -> 6.3 | AI2: =ModelBear!$F$8*Retentie!$B$35 -> 6.3 | AJ2: =ModelBear!$F$8*Retentie!$B$36 -> 6.075 | AK2: =ModelBear!$F$8*Retentie!$B$37 -> 6.075
A3: 2 | C3: =ModelBear!$F$9*Retentie!$B$2 -> 63 | D3: =ModelBear!$F$9*Retentie!$B$3 -> 17.64 | E3: =ModelBear!$F$9*Retentie!$B$4 -> 11.34 | F3: =ModelBear!$F$9*Retentie!$B$5 -> 8.19 | G3: =ModelBear!$F$9*Retentie!$B$6 -> 6.3 | H3: =ModelBear!$F$9*Retentie!$B$7 -> 5.355 | I3: =ModelBear!$F$9*Retentie!$B$8 -> 4.725 | J3: =ModelBear!$F$9*Retentie!$B$9 -> 4.284 | K3: =ModelBear!$F$9*Retentie!$B$10 -> 3.906 | L3: =ModelBear!$F$9*Retentie!$B$11 -> 3.654 | M3: =ModelBear!$F$9*Retentie!$B$12 -> 3.402 | N3: =ModelBear!$F$9*Retentie!$B$13 -> 3.213 | O3: =ModelBear!$F$9*Retentie!$B$14 -> 3.024 | P3: =ModelBear!$F$9*Retentie!$B$15 -> 2.898 | Q3: =ModelBear!$F$9*Retentie!$B$16 -> 2.772 | R3: =ModelBear!$F$9*Retentie!$B$17 -> 2.709 | S3: =ModelBear!$F$9*Retentie!$B$18 -> 2.646 | T3: =ModelBear!$F$9*Retentie!$B$19 -> 2.583 | U3: =ModelBear!$F$9*Retentie!$B$20 -> 2.52 | V3: =ModelBear!$F$9*Retentie!$B$21 -> 2.457 | W3: =ModelBear!$F$9*Retentie!$B$22 -> 2.394 | X3: =ModelBear!$F$9*Retentie!$B$23 -> 2.331 | Y3: =ModelBear!$F$9*Retentie!$B$24 -> 2.268 | Z3: =ModelBear!$F$9*Retentie!$B$25 -> 2.205 | AA3: =ModelBear!$F$9*Retentie!$B$26 -> 2.142 | AB3: =ModelBear!$F$9*Retentie!$B$27 -> 2.079 | AC3: =ModelBear!$F$9*Retentie!$B$28 -> 2.016 | AD3: =ModelBear!$F$9*Retentie!$B$29 -> 1.953 | AE3: =ModelBear!$F$9*Retentie!$B$30 -> 1.89 | AF3: =ModelBear!$F$9*Retentie!$B$31 -> 1.89 | AG3: =ModelBear!$F$9*Retentie!$B$32 -> 1.827 | AH3: =ModelBear!$F$9*Retentie!$B$33 -> 1.827 | AI3: =ModelBear!$F$9*Retentie!$B$34 -> 1.764 | AJ3: =ModelBear!$F$9*Retentie!$B$35 -> 1.764 | AK3: =ModelBear!$F$9*Retentie!$B$36 -> 1.701
A4: 3 | D4: =ModelBear!$F$10*Retentie!$B$2 -> 63 | E4: =ModelBear!$F$10*Retentie!$B$3 -> 17.64 | F4: =ModelBear!$F$10*Retentie!$B$4 -> 11.34 | G4: =ModelBear!$F$10*Retentie!$B$5 -> 8.19 | H4: =ModelBear!$F$10*Retentie!$B$6 -> 6.3 | I4: =ModelBear!$F$10*Retentie!$B$7 -> 5.355 | J4: =ModelBear!$F$10*Retentie!$B$8 -> 4.725 | K4: =ModelBear!$F$10*Retentie!$B$9 -> 4.284 | L4: =ModelBear!$F$10*Retentie!$B$10 -> 3.906 | M4: =ModelBear!$F$10*Retentie!$B$11 -> 3.654 | N4: =ModelBear!$F$10*Retentie!$B$12 -> 3.402 | O4: =ModelBear!$F$10*Retentie!$B$13 -> 3.213 | P4: =ModelBear!$F$10*Retentie!$B$14 -> 3.024 | Q4: =ModelBear!$F$10*Retentie!$B$15 -> 2.898 | R4: =ModelBear!$F$10*Retentie!$B$16 -> 2.772 | S4: =ModelBear!$F$10*Retentie!$B$17 -> 2.709 | T4: =ModelBear!$F$10*Retentie!$B$18 -> 2.646 | U4: =ModelBear!$F$10*Retentie!$B$19 -> 2.583 | V4: =ModelBear!$F$10*Retentie!$B$20 -> 2.52 | W4: =ModelBear!$F$10*Retentie!$B$21 -> 2.457 | X4: =ModelBear!$F$10*Retentie!$B$22 -> 2.394 | Y4: =ModelBear!$F$10*Retentie!$B$23 -> 2.331 | Z4: =ModelBear!$F$10*Retentie!$B$24 -> 2.268 | AA4: =ModelBear!$F$10*Retentie!$B$25 -> 2.205 | AB4: =ModelBear!$F$10*Retentie!$B$26 -> 2.142 | AC4: =ModelBear!$F$10*Retentie!$B$27 -> 2.079 | AD4: =ModelBear!$F$10*Retentie!$B$28 -> 2.016 | AE4: =ModelBear!$F$10*Retentie!$B$29 -> 1.953 | AF4: =ModelBear!$F$10*Retentie!$B$30 -> 1.89 | AG4: =ModelBear!$F$10*Retentie!$B$31 -> 1.89 | AH4: =ModelBear!$F$10*Retentie!$B$32 -> 1.827 | AI4: =ModelBear!$F$10*Retentie!$B$33 -> 1.827 | AJ4: =ModelBear!$F$10*Retentie!$B$34 -> 1.764 | AK4: =ModelBear!$F$10*Retentie!$B$35 -> 1.764
A5: 4 | E5: =ModelBear!$F$11*Retentie!$B$2 -> 63 | F5: =ModelBear!$F$11*Retentie!$B$3 -> 17.64 | G5: =ModelBear!$F$11*Retentie!$B$4 -> 11.34 | H5: =ModelBear!$F$11*Retentie!$B$5 -> 8.19 | I5: =ModelBear!$F$11*Retentie!$B$6 -> 6.3 | J5: =ModelBear!$F$11*Retentie!$B$7 -> 5.355 | K5: =ModelBear!$F$11*Retentie!$B$8 -> 4.725 | L5: =ModelBear!$F$11*Retentie!$B$9 -> 4.284 | M5: =ModelBear!$F$11*Retentie!$B$10 -> 3.906 | N5: =ModelBear!$F$11*Retentie!$B$11 -> 3.654 | O5: =ModelBear!$F$11*Retentie!$B$12 -> 3.402 | P5: =ModelBear!$F$11*Retentie!$B$13 -> 3.213 | Q5: =ModelBear!$F$11*Retentie!$B$14 -> 3.024 | R5: =ModelBear!$F$11*Retentie!$B$15 -> 2.898 | S5: =ModelBear!$F$11*Retentie!$B$16 -> 2.772 | T5: =ModelBear!$F$11*Retentie!$B$17 -> 2.709 | U5: =ModelBear!$F$11*Retentie!$B$18 -> 2.646 | V5: =ModelBear!$F$11*Retentie!$B$19 -> 2.583 | W5: =ModelBear!$F$11*Retentie!$B$20 -> 2.52 | X5: =ModelBear!$F$11*Retentie!$B$21 -> 2.457 | Y5: =ModelBear!$F$11*Retentie!$B$22 -> 2.394 | Z5: =ModelBear!$F$11*Retentie!$B$23 -> 2.331 | AA5: =ModelBear!$F$11*Retentie!$B$24 -> 2.268 | AB5: =ModelBear!$F$11*Retentie!$B$25 -> 2.205 | AC5: =ModelBear!$F$11*Retentie!$B$26 -> 2.142 | AD5: =ModelBear!$F$11*Retentie!$B$27 -> 2.079 | AE5: =ModelBear!$F$11*Retentie!$B$28 -> 2.016 | AF5: =ModelBear!$F$11*Retentie!$B$29 -> 1.953 | AG5: =ModelBear!$F$11*Retentie!$B$30 -> 1.89 | AH5: =ModelBear!$F$11*Retentie!$B$31 -> 1.89 | AI5: =ModelBear!$F$11*Retentie!$B$32 -> 1.827 | AJ5: =ModelBear!$F$11*Retentie!$B$33 -> 1.827 | AK5: =ModelBear!$F$11*Retentie!$B$34 -> 1.764
A6: 5 | F6: =ModelBear!$F$12*Retentie!$B$2 -> 63 | G6: =ModelBear!$F$12*Retentie!$B$3 -> 17.64 | H6: =ModelBear!$F$12*Retentie!$B$4 -> 11.34 | I6: =ModelBear!$F$12*Retentie!$B$5 -> 8.19 | J6: =ModelBear!$F$12*Retentie!$B$6 -> 6.3 | K6: =ModelBear!$F$12*Retentie!$B$7 -> 5.355 | L6: =ModelBear!$F$12*Retentie!$B$8 -> 4.725 | M6: =ModelBear!$F$12*Retentie!$B$9 -> 4.284 | N6: =ModelBear!$F$12*Retentie!$B$10 -> 3.906 | O6: =ModelBear!$F$12*Retentie!$B$11 -> 3.654 | P6: =ModelBear!$F$12*Retentie!$B$12 -> 3.402 | Q6: =ModelBear!$F$12*Retentie!$B$13 -> 3.213 | R6: =ModelBear!$F$12*Retentie!$B$14 -> 3.024 | S6: =ModelBear!$F$12*Retentie!$B$15 -> 2.898 | T6: =ModelBear!$F$12*Retentie!$B$16 -> 2.772 | U6: =ModelBear!$F$12*Retentie!$B$17 -> 2.709 | V6: =ModelBear!$F$12*Retentie!$B$18 -> 2.646 | W6: =ModelBear!$F$12*Retentie!$B$19 -> 2.583 | X6: =ModelBear!$F$12*Retentie!$B$20 -> 2.52 | Y6: =ModelBear!$F$12*Retentie!$B$21 -> 2.457 | Z6: =ModelBear!$F$12*Retentie!$B$22 -> 2.394 | AA6: =ModelBear!$F$12*Retentie!$B$23 -> 2.331 | AB6: =ModelBear!$F$12*Retentie!$B$24 -> 2.268 | AC6: =ModelBear!$F$12*Retentie!$B$25 -> 2.205 | AD6: =ModelBear!$F$12*Retentie!$B$26 -> 2.142 | AE6: =ModelBear!$F$12*Retentie!$B$27 -> 2.079 | AF6: =ModelBear!$F$12*Retentie!$B$28 -> 2.016 | AG6: =ModelBear!$F$12*Retentie!$B$29 -> 1.953 | AH6: =ModelBear!$F$12*Retentie!$B$30 -> 1.89 | AI6: =ModelBear!$F$12*Retentie!$B$31 -> 1.89 | AJ6: =ModelBear!$F$12*Retentie!$B$32 -> 1.827 | AK6: =ModelBear!$F$12*Retentie!$B$33 -> 1.827
A7: 6 | G7: =ModelBear!$F$13*Retentie!$B$2 -> 63 | H7: =ModelBear!$F$13*Retentie!$B$3 -> 17.64 | I7: =ModelBear!$F$13*Retentie!$B$4 -> 11.34 | J7: =ModelBear!$F$13*Retentie!$B$5 -> 8.19 | K7: =ModelBear!$F$13*Retentie!$B$6 -> 6.3 | L7: =ModelBear!$F$13*Retentie!$B$7 -> 5.355 | M7: =ModelBear!$F$13*Retentie!$B$8 -> 4.725 | N7: =ModelBear!$F$13*Retentie!$B$9 -> 4.284 | O7: =ModelBear!$F$13*Retentie!$B$10 -> 3.906 | P7: =ModelBear!$F$13*Retentie!$B$11 -> 3.654 | Q7: =ModelBear!$F$13*Retentie!$B$12 -> 3.402 | R7: =ModelBear!$F$13*Retentie!$B$13 -> 3.213 | S7: =ModelBear!$F$13*Retentie!$B$14 -> 3.024 | T7: =ModelBear!$F$13*Retentie!$B$15 -> 2.898 | U7: =ModelBear!$F$13*Retentie!$B$16 -> 2.772 | V7: =ModelBear!$F$13*Retentie!$B$17 -> 2.709 | W7: =ModelBear!$F$13*Retentie!$B$18 -> 2.646 | X7: =ModelBear!$F$13*Retentie!$B$19 -> 2.583 | Y7: =ModelBear!$F$13*Retentie!$B$20 -> 2.52 | Z7: =ModelBear!$F$13*Retentie!$B$21 -> 2.457 | AA7: =ModelBear!$F$13*Retentie!$B$22 -> 2.394 | AB7: =ModelBear!$F$13*Retentie!$B$23 -> 2.331 | AC7: =ModelBear!$F$13*Retentie!$B$24 -> 2.268 | AD7: =ModelBear!$F$13*Retentie!$B$25 -> 2.205 | AE7: =ModelBear!$F$13*Retentie!$B$26 -> 2.142 | AF7: =ModelBear!$F$13*Retentie!$B$27 -> 2.079 | AG7: =ModelBear!$F$13*Retentie!$B$28 -> 2.016 | AH7: =ModelBear!$F$13*Retentie!$B$29 -> 1.953 | AI7: =ModelBear!$F$13*Retentie!$B$30 -> 1.89 | AJ7: =ModelBear!$F$13*Retentie!$B$31 -> 1.89 | AK7: =ModelBear!$F$13*Retentie!$B$32 -> 1.827
A8: 7 | H8: =ModelBear!$F$14*Retentie!$B$2 -> 63 | I8: =ModelBear!$F$14*Retentie!$B$3 -> 17.64 | J8: =ModelBear!$F$14*Retentie!$B$4 -> 11.34 | K8: =ModelBear!$F$14*Retentie!$B$5 -> 8.19 | L8: =ModelBear!$F$14*Retentie!$B$6 -> 6.3 | M8: =ModelBear!$F$14*Retentie!$B$7 -> 5.355 | N8: =ModelBear!$F$14*Retentie!$B$8 -> 4.725 | O8: =ModelBear!$F$14*Retentie!$B$9 -> 4.284 | P8: =ModelBear!$F$14*Retentie!$B$10 -> 3.906 | Q8: =ModelBear!$F$14*Retentie!$B$11 -> 3.654 | R8: =ModelBear!$F$14*Retentie!$B$12 -> 3.402 | S8: =ModelBear!$F$14*Retentie!$B$13 -> 3.213 | T8: =ModelBear!$F$14*Retentie!$B$14 -> 3.024 | U8: =ModelBear!$F$14*Retentie!$B$15 -> 2.898 | V8: =ModelBear!$F$14*Retentie!$B$16 -> 2.772 | W8: =ModelBear!$F$14*Retentie!$B$17 -> 2.709 | X8: =ModelBear!$F$14*Retentie!$B$18 -> 2.646 | Y8: =ModelBear!$F$14*Retentie!$B$19 -> 2.583 | Z8: =ModelBear!$F$14*Retentie!$B$20 -> 2.52 | AA8: =ModelBear!$F$14*Retentie!$B$21 -> 2.457 | AB8: =ModelBear!$F$14*Retentie!$B$22 -> 2.394 | AC8: =ModelBear!$F$14*Retentie!$B$23 -> 2.331 | AD8: =ModelBear!$F$14*Retentie!$B$24 -> 2.268 | AE8: =ModelBear!$F$14*Retentie!$B$25 -> 2.205 | AF8: =ModelBear!$F$14*Retentie!$B$26 -> 2.142 | AG8: =ModelBear!$F$14*Retentie!$B$27 -> 2.079 | AH8: =ModelBear!$F$14*Retentie!$B$28 -> 2.016 | AI8: =ModelBear!$F$14*Retentie!$B$29 -> 1.953 | AJ8: =ModelBear!$F$14*Retentie!$B$30 -> 1.89 | AK8: =ModelBear!$F$14*Retentie!$B$31 -> 1.89
A9: 8 | I9: =ModelBear!$F$15*Retentie!$B$2 -> 63 | J9: =ModelBear!$F$15*Retentie!$B$3 -> 17.64 | K9: =ModelBear!$F$15*Retentie!$B$4 -> 11.34 | L9: =ModelBear!$F$15*Retentie!$B$5 -> 8.19 | M9: =ModelBear!$F$15*Retentie!$B$6 -> 6.3 | N9: =ModelBear!$F$15*Retentie!$B$7 -> 5.355 | O9: =ModelBear!$F$15*Retentie!$B$8 -> 4.725 | P9: =ModelBear!$F$15*Retentie!$B$9 -> 4.284 | Q9: =ModelBear!$F$15*Retentie!$B$10 -> 3.906 | R9: =ModelBear!$F$15*Retentie!$B$11 -> 3.654 | S9: =ModelBear!$F$15*Retentie!$B$12 -> 3.402 | T9: =ModelBear!$F$15*Retentie!$B$13 -> 3.213 | U9: =ModelBear!$F$15*Retentie!$B$14 -> 3.024 | V9: =ModelBear!$F$15*Retentie!$B$15 -> 2.898 | W9: =ModelBear!$F$15*Retentie!$B$16 -> 2.772 | X9: =ModelBear!$F$15*Retentie!$B$17 -> 2.709 | Y9: =ModelBear!$F$15*Retentie!$B$18 -> 2.646 | Z9: =ModelBear!$F$15*Retentie!$B$19 -> 2.583 | AA9: =ModelBear!$F$15*Retentie!$B$20 -> 2.52 | AB9: =ModelBear!$F$15*Retentie!$B$21 -> 2.457 | AC9: =ModelBear!$F$15*Retentie!$B$22 -> 2.394 | AD9: =ModelBear!$F$15*Retentie!$B$23 -> 2.331 | AE9: =ModelBear!$F$15*Retentie!$B$24 -> 2.268 | AF9: =ModelBear!$F$15*Retentie!$B$25 -> 2.205 | AG9: =ModelBear!$F$15*Retentie!$B$26 -> 2.142 | AH9: =ModelBear!$F$15*Retentie!$B$27 -> 2.079 | AI9: =ModelBear!$F$15*Retentie!$B$28 -> 2.016 | AJ9: =ModelBear!$F$15*Retentie!$B$29 -> 1.953 | AK9: =ModelBear!$F$15*Retentie!$B$30 -> 1.89
